Workbook

Sheet Source data
A1: Source data
A2: Upwardly Global, EIN 94-3346127. Public Form 990 figures and the modelled splits this workbook depends on. Restated here so the file stands alone.
A4: Line | B4: FY2019 | C4: FY2020 | D4: FY2021 | E4: FY2022 | F4: FY2023 | G4: FY2024 | H4: Tier | I4: Note
A5: Form 990 as filed
A6: Contributions and grants | B6: 6528091 | C6: 6738370 | D6: 11624463 | E6: 18348946 | F6: 20709887 | G6: 26008174 | H6: PUBLIC
A7: Program service revenue | B7: 353671 | C7: 304509 | D7: 383141 | E7: 1064285 | F7: 1066130 | G7: 1143216 | H7: PUBLIC
A8: Investment and other income | B8: 3602 | C8: 21624 | D8: 237 | E8: 14416 | F8: 672813 | G8: 1429021 | H8: PUBLIC
A9: Less: fundraising event costs and asset-sale losses | B9: -135303 | C9: -48199 | D9: -34318 | E9: -121695 | F9: -57789 | G9: 0 | H9: DERIVED
A10: Total revenue | B10: 6750061 | C10: 7016304 | D10: 11973523 | E10: 19305952 | F10: 22391041 | G10: 28580411 | H10: PUBLIC
A11: Total functional expenses | B11: 5531091 | C11: 5670504 | D11: 6893690 | E11: 9316393 | F11: 13659379 | G11: 18275646 | H11: PUBLIC
A12: Officer compensation | B12: 336307 | C12: 348404 | D12: 537859 | E12: 642262 | F12: 502983 | G12: 1026038 | H12: PUBLIC
A13: Other salaries and wages | B13: 3257098 | C13: 3406913 | D13: 3755210 | E13: 5321071 | F13: 7253251 | G13: 9234306 | H13: PUBLIC
A14: Payroll taxes | B14: 283482 | C14: 290730 | D14: 339149 | E14: 454590 | F14: 606465 | G14: 800307 | H14: PUBLIC
A15: Total assets | B15: 4915534 | C15: 7157462 | D15: 12593796 | E15: 23406064 | F15: 31782416 | G15: 42583791 | H15: PUBLIC
A16: Total liabilities | B16: 461151 | C16: 1357279 | D16: 1713780 | E16: 2536489 | F16: 2181179 | G16: 2676737 | H16: PUBLIC
A17: Net assets | B17: =B15-B16 | C17: =C15-C16 | D17: =D15-D16 | E17: =E15-E16 | F17: =F15-F16 | G17: =G15-G16 | H17: DERIVED
A19: Modelled functional expense split
A20: Program services share | B20: 0.762 | C20: 0.768 | D20: 0.774 | E20: 0.78 | F20: 0.783 | G20: 0.785 | H20: SYNTHETIC
A21: Management and general share | B21: 0.14 | C21: 0.137 | D21: 0.134 | E21: 0.129 | F21: 0.124 | G21: 0.12 | H21: SYNTHETIC
A22: Fundraising share | B22: 0.098 | C22: 0.095 | D22: 0.092 | E22: 0.091 | F22: 0.093 | G22: 0.095 | H22: SYNTHETIC
A24: Derived expense lines
A25: Program services | B25: =B11*B20 | C25: =C11*C20 | D25: =D11*D20 | E25: =E11*E20 | F25: =F11*F20 | G25: =G11*G20
A26: Management and general | B26: =B11*B21 | C26: =C11*C21 | D26: =D11*D21 | E26: =E11*E21 | F26: =F11*F21 | G26: =G11*G21
A27: Fundraising | B27: =B11*B22 | C27: =C11*C22 | D27: =D11*D22 | E27: =E11*E22 | F27: =F11*F22 | G27: =G11*G22
A29: Interpolation anchors (published observations)
A30: 2022 participants | B30: 7041 | H30: PUBLIC
A31: 2025 participants | B31: 13350 | H31: PUBLIC
A32: Participant growth per year | B32: =(B31/B30)^(1/3)-1 | H32: DERIVED
A33: 2022 placements | B33: 1116 | H33: PUBLIC
A34: 2025 placements | B34: 1730 | H34: PUBLIC
A35: Placement growth per year | B35: =(B34/B33)^(1/3)-1 | H35: DERIVED
A37: Program volume
A38: Participants served | B38: =$B$30*(1+$B$32)^(2019-2022) | C38: =$B$30*(1+$B$32)^(2020-2022) | D38: =$B$30*(1+$B$32)^(2021-2022) | E38: =$B$30*(1+$B$32)^(2022-2022) | F38: =$B$30*(1+$B$32)^(2023-2022) | G38: =$B$30*(1+$B$32)^(2024-2022) | H38: DERIVED
A39: Successful outcomes | B39: =$B$33*(1+$B$35)^(2019-2022) | C39: =$B$33*(1+$B$35)^(2020-2022) | D39: =$B$33*(1+$B$35)^(2021-2022) | E39: =$B$33*(1+$B$35)^(2022-2022) | F39: =$B$33*(1+$B$35)^(2023-2022) | G39: =$B$33*(1+$B$35)^(2024-2022) | H39: DERIVED
A41: Participant and placement counts are published for 2022 and 2025 only. Other years are interpolated at constant growth between those two observations, which fixes the series with no free parameters. The back-cast to FY2019 through FY2021 is the weakest link and should be read as illustrative.

Sheet Scenario model
A1: Five-year scenario model
A2: Runs on whichever case is selected on 'Scenario switch'. Column B is the FY2024 actual starting point.
A4: Line | B4: FY2024 A | C4: FY2025 F | D4: FY2026 F | E4: FY2027 F | F4: FY2028 F | G4: FY2029 F | I4: Note
A5: Revenue: donor count x average gift
A6: Individual donations: donors | B6: 8420 | C6: =B6*(1+'Scenario switch'!$E$9)/(1+'Scenario switch'!$B$33) | D6: =C6*(1+'Scenario switch'!$E$9)/(1+'Scenario switch'!$B$33) | E6: =D6*(1+'Scenario switch'!$E$9)/(1+'Scenario switch'!$B$33) | F6: =E6*(1+'Scenario switch'!$E$9)/(1+'Scenario switch'!$B$33) | G6: =F6*(1+'Scenario switch'!$E$9)/(1+'Scenario switch'!$B$33)
A7: Corporate donations: donors | B7: 214 | C7: =B7*(1+'Scenario switch'!$E$10)/(1+'Scenario switch'!$B$33) | D7: =C7*(1+'Scenario switch'!$E$10)/(1+'Scenario switch'!$B$33) | E7: =D7*(1+'Scenario switch'!$E$10)/(1+'Scenario switch'!$B$33) | F7: =E7*(1+'Scenario switch'!$E$10)/(1+'Scenario switch'!$B$33) | G7: =F7*(1+'Scenario switch'!$E$10)/(1+'Scenario switch'!$B$33)
A8: Foundation grants: donors | B8: 63 | C8: =B8*(1+'Scenario switch'!$E$11)/(1+'Scenario switch'!$B$33) | D8: =C8*(1+'Scenario switch'!$E$11)/(1+'Scenario switch'!$B$33) | E8: =D8*(1+'Scenario switch'!$E$11)/(1+'Scenario switch'!$B$33) | F8: =E8*(1+'Scenario switch'!$E$11)/(1+'Scenario switch'!$B$33) | G8: =F8*(1+'Scenario switch'!$E$11)/(1+'Scenario switch'!$B$33)
A9: Government funding: donors | B9: 11 | C9: =B9*(1+'Scenario switch'!$E$12)/(1+'Scenario switch'!$B$33) | D9: =C9*(1+'Scenario switch'!$E$12)/(1+'Scenario switch'!$B$33) | E9: =D9*(1+'Scenario switch'!$E$12)/(1+'Scenario switch'!$B$33) | F9: =E9*(1+'Scenario switch'!$E$12)/(1+'Scenario switch'!$B$33) | G9: =F9*(1+'Scenario switch'!$E$12)/(1+'Scenario switch'!$B$33)
A10: Fundraising events: donors | B10: 1640 | C10: =B10*(1+'Scenario switch'!$E$13)/(1+'Scenario switch'!$B$33) | D10: =C10*(1+'Scenario switch'!$E$13)/(1+'Scenario switch'!$B$33) | E10: =D10*(1+'Scenario switch'!$E$13)/(1+'Scenario switch'!$B$33) | F10: =E10*(1+'Scenario switch'!$E$13)/(1+'Scenario switch'!$B$33) | G10: =F10*(1+'Scenario switch'!$E$13)/(1+'Scenario switch'!$B$33)
A11: Individual donations: average gift | B11: 370.6628 | C11: =B11*(1+'Scenario switch'!$B$33) | D11: =C11*(1+'Scenario switch'!$B$33) | E11: =D11*(1+'Scenario switch'!$B$33) | F11: =E11*(1+'Scenario switch'!$B$33) | G11: =F11*(1+'Scenario switch'!$B$33)
A12: Corporate donations: average gift | B12: 25522.04 | C12: =B12*(1+'Scenario switch'!$B$33) | D12: =C12*(1+'Scenario switch'!$B$33) | E12: =D12*(1+'Scenario switch'!$B$33) | F12: =E12*(1+'Scenario switch'!$B$33) | G12: =F12*(1+'Scenario switch'!$B$33)
A13: Foundation grants: average gift | B13: 181644.39 | C13: =B13*(1+'Scenario switch'!$B$33) | D13: =C13*(1+'Scenario switch'!$B$33) | E13: =D13*(1+'Scenario switch'!$B$33) | F13: =E13*(1+'Scenario switch'!$B$33) | G13: =F13*(1+'Scenario switch'!$B$33)
A14: Government funding: average gift | B14: 449232.1 | C14: =B14*(1+'Scenario switch'!$B$33) | D14: =C14*(1+'Scenario switch'!$B$33) | E14: =D14*(1+'Scenario switch'!$B$33) | F14: =E14*(1+'Scenario switch'!$B$33) | G14: =F14*(1+'Scenario switch'!$B$33)
A15: Fundraising events: average gift | B15: 634.3457 | C15: =B15*(1+'Scenario switch'!$B$33) | D15: =C15*(1+'Scenario switch'!$B$33) | E15: =D15*(1+'Scenario switch'!$B$33) | F15: =E15*(1+'Scenario switch'!$B$33) | G15: =F15*(1+'Scenario switch'!$B$33)
A17: Individual donations | B17: ='Scenario switch'!B28*0.12 | C17: =C6*C11*(1-'Scenario switch'!$B$41) | D17: =D6*D11*(1-'Scenario switch'!$B$41) | E17: =E6*E11*(1-'Scenario switch'!$B$41) | F17: =F6*F11*(1-'Scenario switch'!$B$41) | G17: =G6*G11*(1-'Scenario switch'!$B$41) | I17: Donor count times average gift, less the funding shock.
A18: Corporate donations | B18: ='Scenario switch'!B28*0.21 | C18: =C7*C12*(1-'Scenario switch'!$B$41) | D18: =D7*D12*(1-'Scenario switch'!$B$41) | E18: =E7*E12*(1-'Scenario switch'!$B$41) | F18: =F7*F12*(1-'Scenario switch'!$B$41) | G18: =G7*G12*(1-'Scenario switch'!$B$41)
A19: Foundation grants | B19: ='Scenario switch'!B28*0.44 | C19: =C8*C13*(1-'Scenario switch'!$B$41) | D19: =D8*D13*(1-'Scenario switch'!$B$41) | E19: =E8*E13*(1-'Scenario switch'!$B$41) | F19: =F8*F13*(1-'Scenario switch'!$B$41) | G19: =G8*G13*(1-'Scenario switch'!$B$41)
A20: Government funding | B20: ='Scenario switch'!B28*0.19 | C20: =C9*C14*(1-'Scenario switch'!$B$41) | D20: =D9*D14*(1-'Scenario switch'!$B$41) | E20: =E9*E14*(1-'Scenario switch'!$B$41) | F20: =F9*F14*(1-'Scenario switch'!$B$41) | G20: =G9*G14*(1-'Scenario switch'!$B$41)
A21: Fundraising events | B21: ='Scenario switch'!B28*0.04 | C21: =C10*C15*(1-'Scenario switch'!$B$41) | D21: =D10*D15*(1-'Scenario switch'!$B$41) | E21: =E10*E15*(1-'Scenario switch'!$B$41) | F21: =F10*F15*(1-'Scenario switch'!$B$41) | G21: =G10*G15*(1-'Scenario switch'!$B$41)
A22: Total contributions | B22: ='Scenario switch'!B28 | C22: =SUM(C17:C21) | D22: =SUM(D17:D21) | E22: =SUM(E17:E21) | F22: =SUM(F17:F21) | G22: =SUM(G17:G21)
A23: Program service revenue | B23: ='Scenario switch'!B29 | C23: =B23*(1+'Scenario switch'!$E$14) | D23: =C23*(1+'Scenario switch'!$E$14) | E23: =D23*(1+'Scenario switch'!$E$14) | F23: =E23*(1+'Scenario switch'!$E$14) | G23: =F23*(1+'Scenario switch'!$E$14)
A24: Investment and other income | C24: =C51*'Scenario switch'!$E$18 | D24: =D51*'Scenario switch'!$E$18 | E24: =E51*'Scenario switch'!$E$18 | F24: =F51*'Scenario switch'!$E$18 | G24: =G51*'Scenario switch'!$E$18 | I24: Return on the opening reserve balance, wired below.
A25: Total revenue | B25: ='Scenario switch'!B28+'Scenario switch'!B29 | C25: =C22+C23+C24 | D25: =D22+D23+D24 | E25: =E22+E23+E24 | F25: =F22+F23+F24 | G25: =G22+G23+G24
A27: Program volume and unit cost
A28: Career Coaching: participants | B28: 2050 | C28: =MIN(B28*(1+'Scenario switch'!$E$17),3400) | D28: =MIN(C28*(1+'Scenario switch'!$E$17),3400) | E28: =MIN(D28*(1+'Scenario switch'!$E$17),3400) | F28: =MIN(E28*(1+'Scenario switch'!$E$17),3400) | G28: =MIN(F28*(1+'Scenario switch'!$E$17),3400)
A29: Digital Learning: participants | B29: 7395 | C29: =MIN(B29*(1+'Scenario switch'!$E$17),15000) | D29: =MIN(C29*(1+'Scenario switch'!$E$17),15000) | E29: =MIN(D29*(1+'Scenario switch'!$E$17),15000) | F29: =MIN(E29*(1+'Scenario switch'!$E$17),15000) | G29: =MIN(F29*(1+'Scenario switch'!$E$17),15000)
A30: Credential Support: participants | B30: 700 | C30: =MIN(B30*(1+'Scenario switch'!$E$17),1150) | D30: =MIN(C30*(1+'Scenario switch'!$E$17),1150) | E30: =MIN(D30*(1+'Scenario switch'!$E$17),1150) | F30: =MIN(E30*(1+'Scenario switch'!$E$17),1150) | G30: =MIN(F30*(1+'Scenario switch'!$E$17),1150)
A31: Partner Capacity: participants | B31: 641 | C31: =MIN(B31*(1+'Scenario switch'!$E$17),1500) | D31: =MIN(C31*(1+'Scenario switch'!$E$17),1500) | E31: =MIN(D31*(1+'Scenario switch'!$E$17),1500) | F31: =MIN(E31*(1+'Scenario switch'!$E$17),1500) | G31: =MIN(F31*(1+'Scenario switch'!$E$17),1500)
A32: Career Coaching: cost per participant | B32: 3848.7805 | C32: =B32*(1+'Scenario switch'!$E$15) | D32: =C32*(1+'Scenario switch'!$E$15) | E32: =D32*(1+'Scenario switch'!$E$15) | F32: =E32*(1+'Scenario switch'!$E$15) | G32: =F32*(1+'Scenario switch'!$E$15)
A33: Digital Learning: cost per participant | B33: 300.2028 | C33: =B33*(1+'Scenario switch'!$E$15) | D33: =C33*(1+'Scenario switch'!$E$15) | E33: =D33*(1+'Scenario switch'!$E$15) | F33: =E33*(1+'Scenario switch'!$E$15) | G33: =F33*(1+'Scenario switch'!$E$15)
A34: Credential Support: cost per participant | B34: 4200 | C34: =B34*(1+'Scenario switch'!$E$15) | D34: =C34*(1+'Scenario switch'!$E$15) | E34: =D34*(1+'Scenario switch'!$E$15) | F34: =E34*(1+'Scenario switch'!$E$15) | G34: =F34*(1+'Scenario switch'!$E$15)
A35: Partner Capacity: cost per participant | B35: 2022.4368 | C35: =B35*(1+'Scenario switch'!$E$15) | D35: =C35*(1+'Scenario switch'!$E$15) | E35: =D35*(1+'Scenario switch'!$E$15) | F35: =E35*(1+'Scenario switch'!$E$15) | G35: =F35*(1+'Scenario switch'!$E$15)
A37: Career Coaching: program cost | C37: =C28*C32 | D37: =D28*D32 | E37: =E28*E32 | F37: =F28*F32 | G37: =G28*G32
A38: Digital Learning: program cost | C38: =C29*C33 | D38: =D29*D33 | E38: =E29*E33 | F38: =F29*F33 | G38: =G29*G33
A39: Credential Support: program cost | C39: =C30*C34 | D39: =D30*D34 | E39: =E30*E34 | F39: =F30*F34 | G39: =G30*G34
A40: Partner Capacity: program cost | C40: =C31*C35 | D40: =D31*D35 | E40: =E31*E35 | F40: =F31*F35 | G40: =G31*G35
A42: Expenses
A43: Program services | B43: ='Scenario switch'!B30 | C43: =SUM(C37:C40) | D43: =SUM(D37:D40) | E43: =SUM(E37:E40) | F43: =SUM(F37:F40) | G43: =SUM(G37:G40)
A44: Management and general | B44: ='Scenario switch'!B31 | C44: =B44*(1+'Scenario switch'!$E$16)*(1+'Scenario switch'!$B$34*(C43/B43-1)) | D44: =C44*(1+'Scenario switch'!$E$16)*(1+'Scenario switch'!$B$34*(D43/C43-1)) | E44: =D44*(1+'Scenario switch'!$E$16)*(1+'Scenario switch'!$B$34*(E43/D43-1)) | F44: =E44*(1+'Scenario switch'!$E$16)*(1+'Scenario switch'!$B$34*(F43/E43-1)) | G44: =F44*(1+'Scenario switch'!$E$16)*(1+'Scenario switch'!$B$34*(G43/F43-1)) | I44: Semi-fixed. In the Downside case this does not fall as fast as revenue, which is why the program expense ratio deteriorates exactly when the optics are worst.
A45: Fundraising | B45: ='Scenario switch'!B32 | C45: =B45*(1+'Scenario switch'!$E$16)*(1+'Scenario switch'!$B$35*(C22/B22-1)) | D45: =C45*(1+'Scenario switch'!$E$16)*(1+'Scenario switch'!$B$35*(D22/C22-1)) | E45: =D45*(1+'Scenario switch'!$E$16)*(1+'Scenario switch'!$B$35*(E22/D22-1)) | F45: =E45*(1+'Scenario switch'!$E$16)*(1+'Scenario switch'!$B$35*(F22/E22-1)) | G45: =F45*(1+'Scenario switch'!$E$16)*(1+'Scenario switch'!$B$35*(G22/F22-1))
...

Sheet Scenario comparison
A1: Scenario comparison
A2: All three cases at once. Values computed by the model engine rather than live formulas, because a single scenario switch can only hold one case at a time. 'Scenario model' is the live version.
A4: Downside case
A5: Metric | B5: FY2025 | C5: FY2026 | D5: FY2027 | E5: FY2028 | F5: FY2029 | H5: Note
A6: Total revenue | B6: 22448864 | C6: 18352719 | D6: 15086008 | E6: 12453437 | F6: 10308162
A7: Total expenses | B7: 18050061 | C7: 17841947 | D7: 17650373 | E7: 17474533 | F7: 17313740
A8: Operating result | B8: 4398803.5 | C8: 510771.34 | D8: -2564365.5 | E8: -5021096.1 | F8: -7005577.7
A9: Operating margin | B9: 0.19594771 | C9: 0.027830827 | D9: -0.16998305 | E9: -0.40318957 | F9: -0.67961463
A10: Closing liquid reserves | B10: 40648804 | C10: 41159575 | D10: 38595209 | E10: 33574113 | F10: 26568536
A11: Liquid reserve runway | B11: 27.024045 | C11: 27.682791 | D11: 26.239814 | E11: 23.055801 | F11: 18.414417
A12: Closing net assets | B12: 44305858 | C12: 44816629 | D12: 42252263 | E12: 37231167 | F12: 30225590
A13: Net assets / expenses | B13: 2.4546099 | C13: 2.5118687 | D13: 2.3938453 | E13: 2.1305958 | F13: 1.7457574
A14: Program expense ratio | B14: 0.7824117 | C14: 0.77918997 | D14: 0.77535987 | E14: 0.7709447 | F14: 0.76596607
A15: Participants served | B15: 9923.12 | C15: 9129.2704 | D15: 8398.9288 | E15: 7727.0145 | F15: 7108.8533
A16: Successful outcomes | B16: 1374.48 | C16: 1264.5216 | D16: 1163.3599 | E16: 1070.2911 | F16: 984.6678
A17: Cost per successful outcome | B17: 10274.852 | C17: 10994.092 | D17: 11763.678 | E17: 12587.135 | F17: 13468.235
A18: Implied FTE | B18: 111.32 | C18: 102.4144 | D18: 94.221248 | E18: 86.683548 | F18: 79.748864
A20: Base case
A21: Metric | B21: FY2025 | C21: FY2026 | D21: FY2027 | E21: FY2028 | F21: FY2029 | H21: Note
A22: Total revenue | B22: 27749073 | C22: 27376797 | D22: 27025706 | E22: 26684543 | F22: 26341677
A23: Total expenses | B23: 19873119 | C23: 21621825 | D23: 23536072 | E23: 25631521 | F23: 27925324
A24: Operating result | B24: 7875954.5 | C24: 5754972.1 | D24: 3489634.2 | E24: 1053021.4 | F24: -1583647
A25: Operating margin | B25: 0.28382766 | C25: 0.21021349 | D25: 0.12912278 | E25: 0.039461849 | F25: -0.060119448
A26: Closing liquid reserves | B26: 44125955 | C26: 49880927 | D26: 53370561 | E26: 54423582 | F26: 52839935
A27: Liquid reserve runway | B27: 26.644608 | C27: 27.683653 | D27: 27.211284 | E27: 25.479681 | F27: 22.706244
A28: Closing net assets | B28: 47783009 | C28: 53537981 | D28: 57027615 | E28: 58080636 | F28: 56496989
A29: Net assets / expenses | B29: 2.4044041 | C29: 2.4761083 | D29: 2.4229878 | E29: 2.2659847 | F29: 2.0231454
A30: Program expense ratio | B30: 0.79199525 | C30: 0.79862421 | D30: 0.80490951 | E30: 0.81087305 | F30: 0.81653585
A31: Participants served | B31: 11433.16 | C31: 12119.15 | D31: 12846.299 | E31: 13617.076 | F31: 14434.101
A32: Successful outcomes | B32: 1583.64 | C32: 1678.6584 | D32: 1779.3779 | E32: 1886.1406 | F32: 1999.309
A33: Cost per successful outcome | B33: 9938.7587 | C33: 10286.615 | D33: 10646.647 | E33: 11019.279 | F33: 11404.954
A34: Implied FTE | B34: 128.26 | C34: 135.9556 | D34: 144.11294 | E34: 152.75971 | F34: 161.92529
A36: Upside case
A37: Metric | B37: FY2025 | C37: FY2026 | D37: FY2027 | E37: FY2028 | F37: FY2029 | H37: Note
A38: Total revenue | B38: 31746272 | C38: 35206665 | D38: 38981619 | E38: 43093763 | F38: 47671483
A39: Total expenses | B39: 21269719 | C39: 24780555 | D39: 28899853 | E39: 31821003 | F39: 33671222
A40: Operating result | B40: 10476553 | C40: 10426110 | D40: 10081765 | E40: 11272760 | F40: 14000261
A41: Operating margin | B41: 0.33000892 | C41: 0.29614024 | D41: 0.25862869 | E41: 0.26158681 | F41: 0.29368209
A42: Closing liquid reserves | B42: 46726553 | C42: 57152663 | D42: 67234428 | E42: 78507188 | F42: 92507449
A43: Liquid reserve runway | B43: 26.362296 | C43: 27.676215 | D43: 27.917551 | E43: 29.6058 | F43: 32.968491
...

Sheet Scenario switch
A1: Scenario switch and driver table
A2: Pick a case in the yellow cell. Every sheet in this workbook recalculates. The three cases are also shown side by side on 'Scenario comparison'.
A4: Active scenario | B4: Base
A5: Scenario index | B5: =MATCH(B4,{"Downside","Base","Upside"},0)
A7: Scenario drivers
A8: Driver | B8: Downside | C8: Base | D8: Upside | E8: Active | F8: Rationale
A9: Individual donation growth | B9: -0.12 | C9: 0.04 | D9: 0.12 | E9: =CHOOSE($B$5,B9,C9,D9)
A10: Corporate donation growth | B10: -0.15 | C10: 0.03 | D10: 0.14 | E10: =CHOOSE($B$5,B10,C10,D10)
A11: Foundation grant growth | B11: -0.22 | C11: -0.06 | D11: 0.08 | E11: =CHOOSE($B$5,B11,C11,D11)
A12: Government funding growth | B12: -0.3 | C12: -0.1 | D12: 0.05 | E12: =CHOOSE($B$5,B12,C12,D12)
A13: Fundraising event growth | B13: -0.1 | C13: 0.02 | D13: 0.09 | E13: =CHOOSE($B$5,B13,C13,D13)
A14: Program service revenue growth | B14: -0.05 | C14: 0.08 | D14: 0.18 | E14: =CHOOSE($B$5,B14,C14,D14)
A15: Cost per participant inflation | B15: 0.07 | C15: 0.035 | D15: 0.02 | E15: =CHOOSE($B$5,B15,C15,D15)
A16: Personnel cost inflation | B16: 0.05 | C16: 0.04 | D16: 0.035 | E16: =CHOOSE($B$5,B16,C16,D16)
A17: Participant growth | B17: -0.08 | C17: 0.06 | D17: 0.16 | E17: =CHOOSE($B$5,B17,C17,D17)
A18: Return on investment balance | B18: 0.018 | C18: 0.038 | D18: 0.055 | E18: =CHOOSE($B$5,B18,C18,D18)
A20: What each case assumes
A21: Downside | B21: Emergency appropriations lapse without replacement and a major foundation cycles out. Government funding falls 30% a year and foundation grants 22%. Cost per participant inflation runs at 7% because the fixed cost base does not shrink as fast as volume. This is the case the reserve exists for, and the case the minimum-funding analysis is built around.
A22: Base | B22: Humanitarian-response funding normalizes gradually. Foundation grants decline 6% a year and government funding 10% a year as emergency appropriations lapse, partly offset by growth in individual, corporate and earned revenue. Participants grow 6% a year and cost per participant rises 3.5%. Management holds headcount roughly flat in real terms.
A23: Upside | B23: The organization converts surge-period relationships into durable multi-year commitments. Foundation funding resumes growth at 8% and government funding stabilizes. Corporate partnerships scale with the employer network. Participants grow 16% a year while cost per participant inflation stays at 2% through digital channel mix shift.
A25: Base year and cost behaviour
A26: FY2024 liquid reserves (opening balance) | B26: ='Source data'!G15*0.8512628666621063
A27: FY2024 net assets | B27: ='Source data'!G17
A28: FY2024 contributions | B28: ='Source data'!G6
A29: FY2024 program service revenue | B29: ='Source data'!G7
A30: FY2024 program services expense | B30: ='Source data'!G25
A31: FY2024 management and general | B31: ='Source data'!G26
A32: FY2024 fundraising | B32: ='Source data'!G27
A33: Average gift inflation | B33: 0.02
A34: Management and general, variable share | B34: 0.35
A35: Fundraising, variable share | B35: 0.5
A36: Reserve floor (months of expenses) | B36: 6
A37: BBB net asset ceiling (multiple of expenses) | B37: 3
A38: Largest single funder, share of revenue | B38: 0.18
A40: Funding shock (drives the sensitivity analysis)
A41: Permanent reduction in contributions from FY2025 | B41: 0 | F41: Set this to 0.10, 0.20 or 0.30 to see the effect on the scenario sheets. The sensitivity table runs the same shocks automatically, so this cell is for exploring, not reporting.
A43: Independent analysis prepared from public information for portfolio and educational purposes. Not affiliated with, endorsed by, or reviewed by Upwardly Global. Historical totals are as filed; all forward-looking and program-level figures are analyst assumptions and are not the organization's plans or guidance.

Sheet Funding sensitivity
A1: Funding sensitivity and minimum viable funding
A2: What happens to results, liquidity, program capacity and beneficiaries if contributions fall permanently. Run on the Base case with the reserve floor enforced, so a funding cut forces a program cut rather than an eternal deficit.
A4: Permanent reduction in contributions from FY2025
A5: Metric | B5: 0% cut | C5: 10% cut | D5: 20% cut | E5: 30% cut | F5: 40% cut | G5: 50% cut | I5: Note
A6: FY2029 operating result | B6: -1583647 | C6: -4119478.4 | D6: -6655309.8 | E6: -9191141.2 | F6: -4818222.9 | G6: -2317147.8 | I6: After any forced program contraction.
A7: FY2029 structural result | B7: -1583647 | C7: -4119478.4 | D7: -6655309.8 | E7: -9191141.2 | F7: -11726973 | G7: -14262804 | I7: Before contraction - what the deficit would be if the organization refused to cut.
A8: Cumulative five-year result | B8: 16589935 | C8: 4231429.6 | D8: -8127076.1 | E8: -20485582 | F8: -25935338 | G8: -28410107
A9: Closing liquid reserves | B9: 52839935 | C9: 40481430 | D9: 28122924 | E9: 15764418 | F9: 10314662 | G9: 7839892.6
A10: Liquid reserve runway | B10: 22.706244 | C10: 17.456096 | D10: 12.16929 | E10: 6.8454422 | F10: 6 | G10: 6
A11: Net assets, months | B11: 24.277744 | C11: 19.033063 | D11: 13.751762 | E11: 8.4334584 | F11: 8.1272945 | G11: 8.7988042
A12: Participants served, FY2029 | B12: 14434.101 | C12: 14434.101 | D12: 14434.101 | E12: 14434.101 | F12: 10396.304 | G12: 7591.889
A13: Successful outcomes, FY2029 | B13: 1999.309 | C13: 1999.309 | D13: 1999.309 | E13: 1999.309 | F13: 1440.022 | G13: 1051.5745
A14: Program capacity retained | B14: 1 | C14: 1 | D14: 1 | E14: 1 | F14: 0.72025986 | G14: 0.52596895 | I14: Against the no-shock Base case. Below 100% means programs were cut to hold the floor.
A15: Beneficiaries forgone | B15: 0 | C15: 0 | D15: 0 | E15: 0 | F15: 4037.7974 | G15: 6842.2121
A16: Outcomes forgone | B16: 0 | C16: 0 | D16: 0 | E16: 0 | F16: 559.28697 | G16: 947.73455
A17: Years until the reserve floor | B17: 9 | C17: 8 | D17: 7 | E17: 6 | F17: 5 | G17: 4 | I17: Tested over sixteen years. This is the vulnerability measure a board can act on.
A20: What if the largest single funder is lost
A21: Share of total revenue at risk | B21: 0.18
A22: Equivalent share of contributions | B22: 0.1978022
A23: Contributions lost in FY2025 | B23: 4972134.1
A24: FY2029 operating result | B24: -6599577.3
A25: FY2029 result without the loss | B25: -1583647
A26: Cumulative five-year shortfall | B26: 24445396
A27: Closing liquid reserves | B27: 28394539
A28: Liquid reserve runway at FY2029 | B28: 12.28588
A29: Years until the reserve floor | B29: 7
A30: Years until the floor without the loss | B30: 9
A31: Program capacity retained | B31: 1
A33: Two different funding floors
A34: These answer different questions and quoting either one alone is misleading. The reserve threshold is how far funding can fall before the balance sheet forces a program cut. The structural threshold is the funding level at which the organization stops breaking even at all. The gap between them is the time the balance sheet buys management to fix an income statement problem.
A35: Reserve threshold: maximum sustainable funding cut | B35: 0.31581608
A36: contributions at that level, FY2025 | B36: 17198263
A37: headroom below the Base case | B37: 7938637.2
A38: Structural threshold: funding uplift needed to break even by FY2029 | B38: 0.062450802
A39: Base case turns to deficit in | B39: 2029
A40: deficit in that year | B40: 1583647
A41: Years of reserve at Base case with no shock | B41: 9
A43: The expense lever, Downside case
A44: Expense reduction needed to hold the floor | B44: 0
A45: Lowest runway reached | B45: 18.414417
...
