Workbook

Sheet Dashboard
A1: Financial dashboard
A2: Upwardly Global | FY2019 - FY2024 actual, FY2025 - FY2027 Base case forecast
B4: FY2024 total revenue | C4: FY2024 operating result | D4: Program expense ratio | E4: Cost to raise $1 | F4: Liquid reserve runway | G4: Net assets / expenses
B5: ='Historical analysis'!G10 | C5: ='Historical analysis'!G19 | D5: ='Historical analysis'!G44 | E5: ='Historical analysis'!G47 | F5: ='Historical analysis'!G53 | G5: ='Historical analysis'!G55
A7: Revenue, expenses and result
C8: FY2019 | D8: FY2020 | E8: FY2021 | F8: FY2022 | G8: FY2023 | H8: FY2024 | I8: FY2025 | J8: FY2026 | K8: FY2027
B9: Total revenue | C9: ='Historical analysis'!B10 | D9: ='Historical analysis'!C10 | E9: ='Historical analysis'!D10 | F9: ='Historical analysis'!E10 | G9: ='Historical analysis'!F10 | H9: ='Historical analysis'!G10 | I9: ='Forecast'!C26 | J9: ='Forecast'!D26 | K9: ='Forecast'!E26
B10: Total expenses | C10: ='Historical analysis'!B16 | D10: ='Historical analysis'!C16 | E10: ='Historical analysis'!D16 | F10: ='Historical analysis'!E16 | G10: ='Historical analysis'!F16 | H10: ='Historical analysis'!G16 | I10: ='Forecast'!C48 | J10: ='Forecast'!D48 | K10: ='Forecast'!E48
B11: Operating result | C11: ='Historical analysis'!B19 | D11: ='Historical analysis'!C19 | E11: ='Historical analysis'!D19 | F11: ='Historical analysis'!E19 | G11: ='Historical analysis'!F19 | H11: ='Historical analysis'!G19 | I11: ='Forecast'!C58 | J11: ='Forecast'!D58 | K11: ='Forecast'!E58
B12: Liquid reserves | C12: ='Historical analysis'!B35 | D12: ='Historical analysis'!C35 | E12: ='Historical analysis'!D35 | F12: ='Historical analysis'!E35 | G12: ='Historical analysis'!F35 | H12: ='Historical analysis'!G35 | I12: ='Forecast'!C61 | J12: ='Forecast'!D61 | K12: ='Forecast'!E61
B13: Participants | C13: ='Historical analysis'!B59 | D13: ='Historical analysis'!C59 | E13: ='Historical analysis'!D59 | F13: ='Historical analysis'!E59 | G13: ='Historical analysis'!F59 | H13: ='Historical analysis'!G59 | I13: ='Forecast'!C68 | J13: ='Forecast'!D68 | K13: ='Forecast'!E68
B14: Successful outcomes | C14: ='Historical analysis'!B60 | D14: ='Historical analysis'!C60 | E14: ='Historical analysis'!D60 | F14: ='Historical analysis'!E60 | G14: ='Historical analysis'!F60 | H14: ='Historical analysis'!G60 | I14: ='Forecast'!C69 | J14: ='Forecast'!D69 | K14: ='Forecast'!E69
B15: Program expense ratio | C15: ='Historical analysis'!B44 | D15: ='Historical analysis'!C44 | E15: ='Historical analysis'!D44 | F15: ='Historical analysis'!E44 | G15: ='Historical analysis'!F44 | H15: ='Historical analysis'!G44 | I15: ='Forecast'!C70 | J15: ='Forecast'!D70 | K15: ='Forecast'!E70
B16: Liquid reserve runway | C16: ='Historical analysis'!B53 | D16: ='Historical analysis'!C53 | E16: ='Historical analysis'!D53 | F16: ='Historical analysis'!E53 | G16: ='Historical analysis'!F53 | H16: ='Historical analysis'!G53 | I16: ='Forecast'!C64 | J16: ='Forecast'!D64 | K16: ='Forecast'!E64
B17: Cost per outcome | C17: ='Historical analysis'!B63 | D17: ='Historical analysis'!C63 | E17: ='Historical analysis'!D63 | F17: ='Historical analysis'!E63 | G17: ='Historical analysis'!F63 | H17: ='Historical analysis'!G63 | I17: ='Forecast'!C72 | J17: ='Forecast'!D72 | K17: ='Forecast'!E72

Sheet Form 990 data
A1: Form 990 data
A2: Upwardly Global, EIN 94-3346127. Figures as filed. Blue cells are inputs; nothing on this sheet is calculated except the two identity checks.
A4: Line | B4: FY2019 | C4: FY2020 | D4: FY2021 | E4: FY2022 | F4: FY2023 | G4: FY2024 | H4: Tier | I4: Note
A5: Revenue
A6: Contributions and grants | B6: 6528091 | C6: 6738370 | D6: 11624463 | E6: 18348946 | F6: 20709887 | G6: 26008174 | H6: PUBLIC | I6: Form 990 Part VIII line 1h. FY2024 derived from the published 91% revenue mix.
A7: Program service revenue | B7: 353671 | C7: 304509 | D7: 383141 | E7: 1064285 | F7: 1066130 | G7: 1143216 | H7: PUBLIC | I7: Form 990 Part VIII line 2g. FY2024 derived from the published 4% share.
A8: Investment and other income | B8: 3602 | C8: 21624 | D8: 237 | E8: 14416 | F8: 672813 | G8: 1429021 | H8: PUBLIC | I8: Form 990 Part VIII line 3 and other. FY2024 is the residual of the derived mix.
A9: Less: fundraising event costs and net asset-sale losses | B9: -135303 | C9: -48199 | D9: -34318 | E9: -121695 | F9: -57789 | G9: 0 | H9: DERIVED | I9: Total revenue less the sum of contributions, program service revenue and investment income. It captures the direct expenses of fundraising events and net losses on asset sales, both of which
A10: Total revenue | B10: 6750061 | C10: 7016304 | D10: 11973523 | E10: 19305952 | F10: 22391041 | G10: 28580411 | H10: PUBLIC | I10: Form 990 Part I line 12, stated net.
A11: Check: components equal total | B11: =IF(ABS(B6+B7+B8+B9-B10)<1,"ok","CHECK") | C11: =IF(ABS(C6+C7+C8+C9-C10)<1,"ok","CHECK") | D11: =IF(ABS(D6+D7+D8+D9-D10)<1,"ok","CHECK") | E11: =IF(ABS(E6+E7+E8+E9-E10)<1,"ok","CHECK") | F11: =IF(ABS(F6+F7+F8+F9-F10)<1,"ok","CHECK") | G11: =IF(ABS(G6+G7+G8+G9-G10)<1,"ok","CHECK")
A12: Form 990 reports gross contributions, gross program service revenue and gross investment income, but states total revenue net of the direct expenses of fundraising events and of losses on asset sales. The three gross lines therefore sum to more than reported total revenue in FY2019 through FY2023. Carrying that difference on its own line is what makes the analysis tie to the filing instead of quietly overstating revenue by between $34,000 and $135,000 a year.
A13: Expenses and personnel
A14: Officer compensation | B14: 336307 | C14: 348404 | D14: 537859 | E14: 642262 | F14: 502983 | G14: 1026038 | H14: PUBLIC | I14: Form 990 Part IX line 5.
A15: Other salaries and wages | B15: 3257098 | C15: 3406913 | D15: 3755210 | E15: 5321071 | F15: 7253251 | G15: 9234306 | H15: PUBLIC | I15: Form 990 Part IX line 7.
A16: Payroll taxes | B16: 283482 | C16: 290730 | D16: 339149 | E16: 454590 | F16: 606465 | G16: 800307 | H16: PUBLIC | I16: Form 990 Part IX line 10. FY2024 derived at the FY2023 effective rate of 7.82%.
A17: Total functional expenses | B17: 5531091 | C17: 5670504 | D17: 6893690 | E17: 9316393 | F17: 13659379 | G17: 18275646 | H17: PUBLIC | I17: Form 990 Part I line 18.
A19: Balance sheet
A20: Total assets | B20: 4915534 | C20: 7157462 | D20: 12593796 | E20: 23406064 | F20: 31782416 | G20: 42583791 | H20: PUBLIC | I20: Form 990 Part I line 20, end of year.
A21: Total liabilities | B21: 461151 | C21: 1357279 | D21: 1713780 | E21: 2536489 | F21: 2181179 | G21: 2676737 | H21: PUBLIC | I21: Form 990 Part I line 21. FY2024 derived as assets less published net assets.
A22: Net assets | B22: =B20-B21 | C22: =C20-C21 | D22: =D20-D21 | E22: =E20-E21 | F22: =F20-F21 | G22: =G20-G21 | H22: DERIVED | I22: Assets less liabilities. FY2024 ties to the published net asset figure of $39,907,054.
A23: Check: FY2024 ties to filed net assets | G23: =IF(ABS(G22-39907054)<1,"ok","CHECK")
A25: Published impact metrics
A26: Participants served | B26: =$B$30*(1+$B$32)^(2019-2022) | C26: =$B$30*(1+$B$32)^(2020-2022) | D26: =$B$30*(1+$B$32)^(2021-2022) | E26: 7041 | F26: =$B$30*(1+$B$32)^(2023-2022) | G26: =$B$30*(1+$B$32)^(2024-2022) | H26: DERIVED | I26: Published for 2022 and 2025 only; other years interpolated at constant growth between those two observations.
A27: Successful outcomes (placements) | B27: =$B$33*(1+$B$35)^(2019-2022) | C27: =$B$33*(1+$B$35)^(2020-2022) | D27: =$B$33*(1+$B$35)^(2021-2022) | E27: 1116 | F27: =$B$33*(1+$B$35)^(2023-2022) | G27: =$B$33*(1+$B$35)^(2024-2022) | H27: DERIVED
A29: Interpolation anchors
A30: 2022 participants (published) | B30: 7041 | H30: PUBLIC
A31: 2025 participants (published) | B31: 13350 | H31: PUBLIC
A32: Participant growth per year | B32: =(B31/B30)^(1/3)-1 | H32: DERIVED
A33: 2022 placements (published) | B33: 1116 | H33: PUBLIC
A34: 2025 placements (published) | B34: 1730 | H34: PUBLIC
A35: Placement growth per year | B35: =(B34/B33)^(1/3)-1 | H35: DERIVED
A36: 2025 average starting salary | B36: 67580 | H36: PUBLIC
A37: 2025 average salary gain | B37: 58790 | H37: PUBLIC
A39: The interpolation has no free parameters: it is fixed by two published observations and the assumption of constant growth between them. The back-cast to FY2019 through FY2021 is a different matter and is the weakest link in the participant series, because it assumes the same growth rate held through a period that includes the pandemic and the start of the humanitarian response surge.

Sheet Model inputs
A1: Model inputs
A2: Every driver the historical analysis and the forecast run on. Blue cells are inputs you can change; the rest of the workbook recalculates.
A4: Functional expense allocation
A5: Driver | B5: FY2019 | C5: FY2020 | D5: FY2021 | E5: FY2022 | F5: FY2023 | G5: FY2024 | H5: Tier | I5: Note
A6: Program services share | B6: 0.762 | C6: 0.768 | D6: 0.774 | E6: 0.78 | F6: 0.783 | G6: 0.785 | H6: SYNTHETIC | I6: Applied to the filed total expense figure for each year, so program + management and general + fundraising reconciles exactly to the Form 990 total. T
A7: Management and general share | B7: 0.14 | C7: 0.137 | D7: 0.134 | E7: 0.129 | F7: 0.124 | G7: 0.12 | H7: SYNTHETIC | I7: Semi-fixed; grows more slowly than programs as the organization scales.
A8: Fundraising share | B8: 0.098 | C8: 0.095 | D8: 0.092 | E8: 0.091 | F8: 0.093 | G8: 0.095 | H8: SYNTHETIC | I8: Rises slightly in FY2024 as the organization invests in replacing surge funding.
A10: Liquidity composition
A11: Driver | B11: FY2019 | C11: FY2020 | D11: FY2021 | E11: FY2022 | F11: FY2023 | G11: FY2024 | H11: Tier | I11: Note
A12: Cash as a share of total assets | B12: 0.42 | C12: 0.46 | D12: 0.44 | E12: 0.4 | F12: 0.39 | G12: 0.39569046 | H12: SYNTHETIC | I12: Strict cash measure.
A13: Liquid reserves as a share of total assets | B13: 0.72 | C13: 0.76 | D13: 0.82 | E13: 0.86 | F13: 0.84 | G13: 0.85126287 | H13: SYNTHETIC | I13: Cash plus short-term investments - the measure a board treats as available. Both are reported everywhere; they must never be mixed.
A15: Revenue composition (share of contributions)
A16: Category | B16: Share | H16: Tier | I16: Note
A17: Individual donations | B17: 0.12 | H17: SYNTHETIC | I17: Applied to the filed contributions total each year. The heavy weighting toward foundation and government funding is the analytical
A18: Corporate donations | B18: 0.21 | H18: SYNTHETIC | I18: Applied to the filed contributions total each year. The heavy weighting toward foundation and government funding is the analytical
A19: Foundation grants | B19: 0.44 | H19: SYNTHETIC | I19: Applied to the filed contributions total each year. The heavy weighting toward foundation and government funding is the analytical
A20: Government funding | B20: 0.19 | H20: SYNTHETIC | I20: Applied to the filed contributions total each year. The heavy weighting toward foundation and government funding is the analytical
A21: Fundraising events | B21: 0.04 | H21: SYNTHETIC | I21: Applied to the filed contributions total each year. The heavy weighting toward foundation and government funding is the analytical
A23: Revenue drivers: donor count and average gift
A24: Category | B24: FY2024 donors | C24: Retention | D24: FY2024 revenue | E24: Average gift | H24: Tier | I24: Note
A25: Individual donations | B25: 8420 | C25: 0.62 | D25: ='Form 990 data'!G6*B17 | E25: =D25/B25 | H25: SYNTHETIC | I25: Donor counts are assumed; average gift is then solved so that donors x average gift equals the modelled category revenue
A26: Corporate donations | B26: 214 | C26: 0.78 | D26: ='Form 990 data'!G6*B18 | E26: =D26/B26 | H26: SYNTHETIC | I26: Donor counts are assumed; average gift is then solved so that donors x average gift equals the modelled category revenue
A27: Foundation grants | B27: 63 | C27: 0.71 | D27: ='Form 990 data'!G6*B19 | E27: =D27/B27 | H27: SYNTHETIC | I27: Donor counts are assumed; average gift is then solved so that donors x average gift equals the modelled category revenue
A28: Government funding | B28: 11 | C28: 0.83 | D28: ='Form 990 data'!G6*B20 | E28: =D28/B28 | H28: SYNTHETIC | I28: Donor counts are assumed; average gift is then solved so that donors x average gift equals the modelled category revenue
A29: Fundraising events | B29: 1640 | C29: 0.48 | D29: ='Form 990 data'!G6*B21 | E29: =D29/B29 | H29: SYNTHETIC | I29: Donor counts are assumed; average gift is then solved so that donors x average gift equals the modelled category revenue
A30: Total | D30: =SUM(D25:D29)
A31: Check: ties to filed contributions | D31: =IF(ABS(D30-'Form 990 data'!G6)<1,"ok","CHECK")
A33: Program portfolio, FY2024 base year
A34: Program | B34: Participants | C34: Outcomes | D34: Program cost | E34: Completion rate | F34: Salary gain | G34: Staff hrs / participant | H34: Tier | I34: Note
A35: Career Coaching | B35: 2050 | C35: 861 | D35: 7890000 | E35: 0.71 | F35: 61000 | G35: 39 | H35: SYNTHETIC | I35: Intensive one-to-one coaching for work-authorized immigrant and refugee professionals: resume and interview pr
A36: Digital Learning | B36: 7395 | C36: 333 | D36: 2220000 | E36: 0.24 | F36: 37000 | G36: 2.5 | H36: SYNTHETIC | I36: Self-serve online curriculum and community, open to any eligible jobseeker. Very low marginal cost per partici
A37: Credential Support | B37: 700 | C37: 217 | D37: 2940000 | E37: 0.58 | F37: 88000 | G37: 60 | H37: SYNTHETIC | I37: Support for foreign-credentialed professionals - physicians, engineers, accountants - navigating US licensure
A38: Partner Capacity | B38: 641 | C38: 83 | D38: 1296382 | E38: 0.46 | F38: 46500 | G38: 15.584555 | H38: SYNTHETIC | I38: Training and tooling delivered to staff at partner workforce development organizations, who then serve jobseek
A39: Total | B39: =SUM(B35:B38) | C39: =SUM(C35:C38) | D39: =SUM(D35:D38) | G39: =SUM(G35:G38)
A40: Check: costs tie to the program expense pool | D40: =IF(ABS(D39-'Form 990 data'!G17*G6)<1,"ok","CHECK")
A42: Personnel
A43: Full-time equivalents, FY2024 | B43: 121 | H43: SYNTHETIC | I43: FY2024 salaries of $10,260,344 (officer compensation plus other salaries, both public) divided by an assumed 121 FTE gives an average salary
A44: Payroll tax rate | B44: 0.0782 | H44: DERIVED | I44: FY2023 payroll tax divided by FY2023 salaries, both filed figures.
A45: Benefits load | B45: 0.1 | H45: SYNTHETIC | I45: Health, retirement and other benefits as a share of salary.
A46: Productive hours per FTE | B46: 1680 | H46: SYNTHETIC | I46: 2,080 gross hours less leave, training and non-delivery time.
...

Sheet Historical analysis
A1: Historical financial analysis, FY2019 - FY2024
A2: All figures calculated from the Form 990 data and model input sheets. Nothing on this sheet is typed in.
A4: Line | B4: FY2019 | C4: FY2020 | D4: FY2021 | E4: FY2022 | F4: FY2023 | G4: FY2024 | I4: Note
A5: Statement of activities
A6: Contributions and grants | B6: ='Form 990 data'!B6 | C6: ='Form 990 data'!C6 | D6: ='Form 990 data'!D6 | E6: ='Form 990 data'!E6 | F6: ='Form 990 data'!F6 | G6: ='Form 990 data'!G6
A7: Program service revenue | B7: ='Form 990 data'!B7 | C7: ='Form 990 data'!C7 | D7: ='Form 990 data'!D7 | E7: ='Form 990 data'!E7 | F7: ='Form 990 data'!F7 | G7: ='Form 990 data'!G7
A8: Investment and other income | B8: ='Form 990 data'!B8 | C8: ='Form 990 data'!C8 | D8: ='Form 990 data'!D8 | E8: ='Form 990 data'!E8 | F8: ='Form 990 data'!F8 | G8: ='Form 990 data'!G8
A9: Less: fundraising event costs and asset-sale losses | B9: ='Form 990 data'!B9 | C9: ='Form 990 data'!C9 | D9: ='Form 990 data'!D9 | E9: ='Form 990 data'!E9 | F9: ='Form 990 data'!F9 | G9: ='Form 990 data'!G9 | H9: DERIVED | I9: Form 990 states total revenue net of these. Without this line the revenue total would not tie to the filing.
A10: Total revenue | B10: =SUM(B6:B9) | C10: =SUM(C6:C9) | D10: =SUM(D6:D9) | E10: =SUM(E6:E9) | F10: =SUM(F6:F9) | G10: =SUM(G6:G9)
A11: Check: ties to filed total revenue | B11: =IF(ABS(B10-'Form 990 data'!B10)<1,"ok","CHECK") | C11: =IF(ABS(C10-'Form 990 data'!C10)<1,"ok","CHECK") | D11: =IF(ABS(D10-'Form 990 data'!D10)<1,"ok","CHECK") | E11: =IF(ABS(E10-'Form 990 data'!E10)<1,"ok","CHECK") | F11: =IF(ABS(F10-'Form 990 data'!F10)<1,"ok","CHECK") | G11: =IF(ABS(G10-'Form 990 data'!G10)<1,"ok","CHECK")
A13: Program services | B13: ='Form 990 data'!B17*'Model inputs'!B6 | C13: ='Form 990 data'!C17*'Model inputs'!C6 | D13: ='Form 990 data'!D17*'Model inputs'!D6 | E13: ='Form 990 data'!E17*'Model inputs'!E6 | F13: ='Form 990 data'!F17*'Model inputs'!F6 | G13: ='Form 990 data'!G17*'Model inputs'!G6 | H13: SYNTHETIC | I13: Filed total expense multiplied by the modelled program share.
A14: Management and general | B14: ='Form 990 data'!B17*'Model inputs'!B7 | C14: ='Form 990 data'!C17*'Model inputs'!C7 | D14: ='Form 990 data'!D17*'Model inputs'!D7 | E14: ='Form 990 data'!E17*'Model inputs'!E7 | F14: ='Form 990 data'!F17*'Model inputs'!F7 | G14: ='Form 990 data'!G17*'Model inputs'!G7 | H14: SYNTHETIC
A15: Fundraising | B15: ='Form 990 data'!B17*'Model inputs'!B8 | C15: ='Form 990 data'!C17*'Model inputs'!C8 | D15: ='Form 990 data'!D17*'Model inputs'!D8 | E15: ='Form 990 data'!E17*'Model inputs'!E8 | F15: ='Form 990 data'!F17*'Model inputs'!F8 | G15: ='Form 990 data'!G17*'Model inputs'!G8 | H15: SYNTHETIC
A16: Total expenses | B16: =SUM(B13:B15) | C16: =SUM(C13:C15) | D16: =SUM(D13:D15) | E16: =SUM(E13:E15) | F16: =SUM(F13:F15) | G16: =SUM(G13:G15)
A17: Check: ties to filed total expenses | B17: =IF(ABS(B16-'Form 990 data'!B17)<1,"ok","CHECK") | C17: =IF(ABS(C16-'Form 990 data'!C17)<1,"ok","CHECK") | D17: =IF(ABS(D16-'Form 990 data'!D17)<1,"ok","CHECK") | E17: =IF(ABS(E16-'Form 990 data'!E17)<1,"ok","CHECK") | F17: =IF(ABS(F16-'Form 990 data'!F17)<1,"ok","CHECK") | G17: =IF(ABS(G16-'Form 990 data'!G17)<1,"ok","CHECK")
A19: Operating surplus / (deficit) | B19: =B10-B16 | C19: =C10-C16 | D19: =D10-D16 | E19: =E10-E16 | F19: =F10-F16 | G19: =G10-G16
A20: Operating margin | B20: =B19/B10 | C20: =C19/C10 | D20: =D19/D10 | E20: =E19/E10 | F20: =F19/F10 | G20: =G19/G10
A22: Natural classification (memo)
A23: Salaries and officer compensation | B23: ='Form 990 data'!B14+'Form 990 data'!B15 | C23: ='Form 990 data'!C14+'Form 990 data'!C15 | D23: ='Form 990 data'!D14+'Form 990 data'!D15 | E23: ='Form 990 data'!E14+'Form 990 data'!E15 | F23: ='Form 990 data'!F14+'Form 990 data'!F15 | G23: ='Form 990 data'!G14+'Form 990 data'!G15
A24: Payroll taxes | B24: ='Form 990 data'!B16 | C24: ='Form 990 data'!C16 | D24: ='Form 990 data'!D16 | E24: ='Form 990 data'!E16 | F24: ='Form 990 data'!F16 | G24: ='Form 990 data'!G16
A25: Benefits | B25: =B23*'Model inputs'!$B$45 | C25: =C23*'Model inputs'!$B$45 | D25: =D23*'Model inputs'!$B$45 | E25: =E23*'Model inputs'!$B$45 | F25: =F23*'Model inputs'!$B$45 | G25: =G23*'Model inputs'!$B$45 | H25: SYNTHETIC | I25: Assumed load; not separately reported in the extract used here.
A26: Total personnel | B26: =SUM(B23:B25) | C26: =SUM(C23:C25) | D26: =SUM(D23:D25) | E26: =SUM(E23:E25) | F26: =SUM(F23:F25) | G26: =SUM(G23:G25)
A27: Non-personnel expenses | B27: =B16-B26 | C27: =C16-C26 | D27: =D16-D26 | E27: =E16-E26 | F27: =F16-F26 | G27: =G16-G26
A28: Personnel as a share of expenses | B28: =B26/B16 | C28: =C26/C16 | D28: =D26/D16 | E28: =E26/E16 | F28: =F26/F16 | G28: =G26/G16
A30: Financial position
A31: Total assets | B31: ='Form 990 data'!B20 | C31: ='Form 990 data'!C20 | D31: ='Form 990 data'!D20 | E31: ='Form 990 data'!E20 | F31: ='Form 990 data'!F20 | G31: ='Form 990 data'!G20
A32: Total liabilities | B32: ='Form 990 data'!B21 | C32: ='Form 990 data'!C21 | D32: ='Form 990 data'!D21 | E32: ='Form 990 data'!E21 | F32: ='Form 990 data'!F21 | G32: ='Form 990 data'!G21
A33: Net assets | B33: =B31-B32 | C33: =C31-C32 | D33: =D31-D32 | E33: =E31-E32 | F33: =F31-F32 | G33: =G31-G32
A34: Cash and equivalents | B34: =B31*'Model inputs'!B12 | C34: =C31*'Model inputs'!C12 | D34: =D31*'Model inputs'!D12 | E34: =E31*'Model inputs'!E12 | F34: =F31*'Model inputs'!F12 | G34: =G31*'Model inputs'!G12 | H34: SYNTHETIC
A35: Liquid reserves (cash plus short-term investments) | B35: =B31*'Model inputs'!B13 | C35: =C31*'Model inputs'!C13 | D35: =D31*'Model inputs'!D13 | E35: =E31*'Model inputs'!E13 | F35: =F31*'Model inputs'!F13 | G35: =G31*'Model inputs'!G13 | H35: SYNTHETIC | I35: The measure a board treats as available. Roughly a year more runway than cash alone.
A37: Growth
A38: Revenue growth | B38: n/a | C38: =C10/B10-1 | D38: =D10/C10-1 | E38: =E10/D10-1 | F38: =F10/E10-1 | G38: =G10/F10-1
A39: Expense growth | B39: n/a | C39: =C16/B16-1 | D39: =D16/C16-1 | E39: =E16/D16-1 | F39: =F16/E16-1 | G39: =G16/F16-1
A40: Contribution growth | B40: n/a | C40: =C6/B6-1 | D40: =D6/C6-1 | E40: =E6/D6-1 | F40: =F6/E6-1 | G40: =G6/F6-1
A41: Growth gap (revenue less expense) | B41: n/a | C41: =C38-C39 | D41: =D38-D39 | E41: =E38-E39 | F41: =F38-F39 | G41: =G38-G39 | I41: Positive means revenue outran spending - the pattern that built the reserve.
A43: Efficiency and stewardship ratios
A44: Program expense ratio | B44: =B13/B16 | C44: =C13/C16 | D44: =D13/D16 | E44: =E13/E16 | F44: =F13/F16 | G44: =G13/G16 | I44: BBB Standard 8 requires at least 65%.
A45: vs BBB minimum (65%) | B45: =B44-'Model inputs'!$B$67 | C45: =C44-'Model inputs'!$B$67 | D45: =D44-'Model inputs'!$B$67 | E45: =E44-'Model inputs'!$B$67 | F45: =F44-'Model inputs'!$B$67 | G45: =G44-'Model inputs'!$B$67
A46: Administrative cost ratio | B46: =B14/B16 | C46: =C14/C16 | D46: =D14/D16 | E46: =E14/E16 | F46: =F14/F16 | G46: =G14/G16
A47: Fundraising cost ratio (cost to raise $1) | B47: =B15/B6 | C47: =C15/C6 | D47: =D15/D6 | E47: =E15/E6 | F47: =F15/F6 | G47: =G15/G6 | I47: BBB Standard 9 caps this at 35 cents. Anything under 10 cents is strong.
...

Sheet Forecast
A1: Three-year forecast, FY2025 - FY2027 (Base case)
A2: Driver based: donation revenue is donor count times average gift, and program cost is participants times cost per participant. Change a driver on 'Model inputs' and every number here moves. Scenarios live in 04_Scenario_Model.xlsx.
A4: Line | B4: FY2024 A | C4: FY2025 E | D4: FY2026 F | E4: FY2027 F | H4: Note
A5: Revenue drivers
A6: Individual donations: donors | B6: ='Model inputs'!B25 | C6: =B6*(1+'Model inputs'!$B$55)/(1+'Model inputs'!$B$50) | D6: =C6*(1+'Model inputs'!$B$55)/(1+'Model inputs'!$B$50) | E6: =D6*(1+'Model inputs'!$B$55)/(1+'Model inputs'!$B$50)
A7: Individual donations: average gift | B7: ='Model inputs'!E25 | C7: =B7*(1+'Model inputs'!$B$50) | D7: =C7*(1+'Model inputs'!$B$50) | E7: =D7*(1+'Model inputs'!$B$50)
A8: Corporate donations: donors | B8: ='Model inputs'!B26 | C8: =B8*(1+'Model inputs'!$B$56)/(1+'Model inputs'!$B$50) | D8: =C8*(1+'Model inputs'!$B$56)/(1+'Model inputs'!$B$50) | E8: =D8*(1+'Model inputs'!$B$56)/(1+'Model inputs'!$B$50)
A9: Corporate donations: average gift | B9: ='Model inputs'!E26 | C9: =B9*(1+'Model inputs'!$B$50) | D9: =C9*(1+'Model inputs'!$B$50) | E9: =D9*(1+'Model inputs'!$B$50)
A10: Foundation grants: donors | B10: ='Model inputs'!B27 | C10: =B10*(1+'Model inputs'!$B$57)/(1+'Model inputs'!$B$50) | D10: =C10*(1+'Model inputs'!$B$57)/(1+'Model inputs'!$B$50) | E10: =D10*(1+'Model inputs'!$B$57)/(1+'Model inputs'!$B$50)
A11: Foundation grants: average gift | B11: ='Model inputs'!E27 | C11: =B11*(1+'Model inputs'!$B$50) | D11: =C11*(1+'Model inputs'!$B$50) | E11: =D11*(1+'Model inputs'!$B$50)
A12: Government funding: donors | B12: ='Model inputs'!B28 | C12: =B12*(1+'Model inputs'!$B$58)/(1+'Model inputs'!$B$50) | D12: =C12*(1+'Model inputs'!$B$58)/(1+'Model inputs'!$B$50) | E12: =D12*(1+'Model inputs'!$B$58)/(1+'Model inputs'!$B$50)
A13: Government funding: average gift | B13: ='Model inputs'!E28 | C13: =B13*(1+'Model inputs'!$B$50) | D13: =C13*(1+'Model inputs'!$B$50) | E13: =D13*(1+'Model inputs'!$B$50)
A14: Fundraising events: donors | B14: ='Model inputs'!B29 | C14: =B14*(1+'Model inputs'!$B$59)/(1+'Model inputs'!$B$50) | D14: =C14*(1+'Model inputs'!$B$59)/(1+'Model inputs'!$B$50) | E14: =D14*(1+'Model inputs'!$B$59)/(1+'Model inputs'!$B$50)
A15: Fundraising events: average gift | B15: ='Model inputs'!E29 | C15: =B15*(1+'Model inputs'!$B$50) | D15: =C15*(1+'Model inputs'!$B$50) | E15: =D15*(1+'Model inputs'!$B$50)
A17: Revenue
A18: Individual donations | B18: ='Model inputs'!D25 | C18: =C6*C7 | D18: =D6*D7 | E18: =E6*E7 | H18: Donor count times average gift.
A19: Corporate donations | B19: ='Model inputs'!D26 | C19: =C8*C9 | D19: =D8*D9 | E19: =E8*E9
A20: Foundation grants | B20: ='Model inputs'!D27 | C20: =C10*C11 | D20: =D10*D11 | E20: =E10*E11
A21: Government funding | B21: ='Model inputs'!D28 | C21: =C12*C13 | D21: =D12*D13 | E21: =E12*E13
A22: Fundraising events | B22: ='Model inputs'!D29 | C22: =C14*C15 | D22: =D14*D15 | E22: =E14*E15
A23: Total contributions and grants | B23: ='Historical analysis'!G6 | C23: =SUM(C18:C22) | D23: =SUM(D18:D22) | E23: =SUM(E18:E22)
A24: Program service revenue | B24: ='Historical analysis'!G7 | C24: =B24*(1+'Model inputs'!$B$60) | D24: =C24*(1+'Model inputs'!$B$60) | E24: =D24*(1+'Model inputs'!$B$60)
A25: Investment and other income | B25: ='Historical analysis'!G8 | C25: =C60*'Model inputs'!$B$64 | D25: =D60*'Model inputs'!$B$64 | E25: =E60*'Model inputs'!$B$64 | H25: Return on the opening liquid reserve balance. This line grows as the reserve grows, which flatters the operating result and is worth separating out.
A26: Total revenue | B26: ='Historical analysis'!G10 | C26: =C23+C24+C25 | D26: =D23+D24+D25 | E26: =E23+E24+E25
A28: Program volume and unit cost
A29: Career Coaching: participants | B29: ='Model inputs'!B35 | C29: =MIN(B29*(1+'Model inputs'!$B$63),3400) | D29: =MIN(C29*(1+'Model inputs'!$B$63),3400) | E29: =MIN(D29*(1+'Model inputs'!$B$63),3400)
A30: Digital Learning: participants | B30: ='Model inputs'!B36 | C30: =MIN(B30*(1+'Model inputs'!$B$63),15000) | D30: =MIN(C30*(1+'Model inputs'!$B$63),15000) | E30: =MIN(D30*(1+'Model inputs'!$B$63),15000)
A31: Credential Support: participants | B31: ='Model inputs'!B37 | C31: =MIN(B31*(1+'Model inputs'!$B$63),1150) | D31: =MIN(C31*(1+'Model inputs'!$B$63),1150) | E31: =MIN(D31*(1+'Model inputs'!$B$63),1150)
A32: Partner Capacity: participants | B32: ='Model inputs'!B38 | C32: =MIN(B32*(1+'Model inputs'!$B$63),1500) | D32: =MIN(C32*(1+'Model inputs'!$B$63),1500) | E32: =MIN(D32*(1+'Model inputs'!$B$63),1500)
A34: Career Coaching: cost per participant | B34: ='Model inputs'!D35/'Model inputs'!B35 | C34: =B34*(1+'Model inputs'!$B$61) | D34: =C34*(1+'Model inputs'!$B$61) | E34: =D34*(1+'Model inputs'!$B$61)
A35: Digital Learning: cost per participant | B35: ='Model inputs'!D36/'Model inputs'!B36 | C35: =B35*(1+'Model inputs'!$B$61) | D35: =C35*(1+'Model inputs'!$B$61) | E35: =D35*(1+'Model inputs'!$B$61)
A36: Credential Support: cost per participant | B36: ='Model inputs'!D37/'Model inputs'!B37 | C36: =B36*(1+'Model inputs'!$B$61) | D36: =C36*(1+'Model inputs'!$B$61) | E36: =D36*(1+'Model inputs'!$B$61)
A37: Partner Capacity: cost per participant | B37: ='Model inputs'!D38/'Model inputs'!B38 | C37: =B37*(1+'Model inputs'!$B$61) | D37: =C37*(1+'Model inputs'!$B$61) | E37: =D37*(1+'Model inputs'!$B$61)
A39: Career Coaching: program cost | B39: ='Model inputs'!D35 | C39: =C29*C34 | D39: =D29*D34 | E39: =E29*E34 | H39: Participants times cost per participant.
A40: Digital Learning: program cost | B40: ='Model inputs'!D36 | C40: =C30*C35 | D40: =D30*D35 | E40: =E30*E35
A41: Credential Support: program cost | B41: ='Model inputs'!D37 | C41: =C31*C36 | D41: =D31*D36 | E41: =E31*E36
A42: Partner Capacity: program cost | B42: ='Model inputs'!D38 | C42: =C32*C37 | D42: =D32*D37 | E42: =E32*E37
A44: Expenses
A45: Program services | B45: ='Historical analysis'!G13 | C45: =SUM(C39:C42) | D45: =SUM(D39:D42) | E45: =SUM(E39:E42)
A46: Management and general | B46: ='Historical analysis'!G14 | C46: =B46*(1+'Model inputs'!$B$62)*(1+'Model inputs'!$B$51*(C45/B45-1)) | D46: =C46*(1+'Model inputs'!$B$62)*(1+'Model inputs'!$B$51*(D45/C45-1)) | E46: =D46*(1+'Model inputs'!$B$62)*(1+'Model inputs'!$B$51*(E45/D45-1)) | H46: Semi-fixed: only the variable share moves with program scale.
...
